<mujoco model="pipe-snake">
  <compiler angle="radian" autolimits="true"/>
  <option timestep="0.001">
    <flag sensornoise="enable"/>
  </option>
  <visual>
    <quality shadowsize="8192"/>
    <headlight ambient="0 0 0" diffuse="0 0 0" specular="1 1 1"/>
  </visual>
  <default class="main">
    <default class="collision">
      <geom type="box" group="3"/>
      <default class="pipe">
        <geom size="0.0015 0.01425 3.5"/>
      </default>
    </default>
  </default>
  <asset>
    <texture type="2d" name="texplane" builtin="checker" mark="cross" rgb2="0.1 0.15 0.2" markrgb="0.8 0.8 0.8" width="512" height="512"/>
    <texture type="cube" name="texgeom" builtin="flat" mark="cross" rgb1="0.8 0.6 0.4" rgb2="0.8 0.6 0.4" markrgb="1 1 1" width="127" height="762"/>
    <material name="floor" reflectance="0.1"/>
    <material name="matplane" texture="texplane" texuniform="true" texrepeat="2 2" reflectance="0.3"/>
    <material name="matgeom" texture="texgeom" texuniform="true" rgba="0.8 0.6 0.4 1"/>
    <mesh name="head_link" file="./asset/Head.stl"/>
    <mesh name="h_link" file="./asset/Link2.stl"/>
    <mesh name="v_link" file="./asset/Link3.stl"/>
    <mesh name="tail_link" file="./asset/Tail.stl"/>
  </asset>
  <worldbody>
    <geom name="floor" size="0 0 0.25" type="plane" condim="6" friction="0.5 0.1 0.01" material="matplane"/>
    <light pos="0 0 15" dir="0 0 -1" castshadow="false" diffuse="1 1 1" specular="0 0 0"/>
    <body name="head" pos="0 0 0.038" gravcomp="0">
      <joint name="root" type="free"/>
      <geom name="head" type="mesh" mass="0.2" mesh="head_link"/>
      <site name="s_head" pos="0 0 0"/>
      <body name="link1" pos="-0.0685 0 0" gravcomp="0">
        <joint name="joint1" pos="0.0685 0 0" axis="0 1 0" range="-1.5708 1.5708" armature="0.1" damping="0.42"/>
        <geom name="link1" type="mesh" mass="0.2" mesh="h_link"/>
        <site name="s_link1" pos="0 0 0"/>
        <body name="link2" pos="-0.0685 0 0" gravcomp="0">
          <joint name="joint2" pos="0.0685 0 0" axis="0 0 1" range="-1.5708 1.5708" armature="0.1" damping="0.42"/>
          <geom name="link2" type="mesh" mass="0.2" mesh="v_link"/>
          <site name="s_link2" pos="0 0 0"/>
          <body name="link3" pos="-0.0685 0 0" gravcomp="0">
            <joint name="joint3" pos="0.0685 0 0" axis="0 1 0" range="-1.5708 1.5708" armature="0.1" damping="0.42"/>
            <geom name="link3" type="mesh" mass="0.2" mesh="h_link"/>
            <site name="s_link3" pos="0 0 0"/>
            <body name="link4" pos="-0.0685 0 0" gravcomp="0">
              <joint name="joint4" pos="0.0685 0 0" axis="0 0 1" range="-1.5708 1.5708" armature="0.1" damping="0.42"/>
              <geom name="link4" type="mesh" mass="0.2" mesh="v_link"/>
              <site name="s_link4" pos="0 0 0"/>
              <body name="link5" pos="-0.0685 0 0" gravcomp="0">
                <joint name="joint5" pos="0.0685 0 0" axis="0 1 0" range="-1.5708 1.5708" armature="0.1" damping="0.42"/>
                <geom name="link5" type="mesh" mass="0.2" mesh="h_link"/>
                <site name="s_link5" pos="0 0 0"/>
                <body name="link6" pos="-0.0685 0 0" gravcomp="0">
                  <joint name="joint6" pos="0.0685 0 0" axis="0 0 1" range="-1.5708 1.5708" armature="0.1" damping="0.42"/>
                  <geom name="link6" type="mesh" mass="0.2" mesh="v_link"/>
                  <site name="s_link6" pos="0 0 0"/>
                  <body name="link7" pos="-0.0685 0 0" gravcomp="0">
                    <joint name="joint7" pos="0.0685 0 0" axis="0 1 0" range="-1.5708 1.5708" armature="0.1" damping="0.42"/>
                    <geom name="link7" type="mesh" mass="0.2" mesh="h_link"/>
                    <site name="s_link7" pos="0 0 0"/>
                    <body name="link8" pos="-0.0685 0 0" gravcomp="0">
                      <joint name="joint8" pos="0.0685 0 0" axis="0 0 1" range="-1.5708 1.5708" armature="0.1" damping="0.42"/>
                      <geom name="link8" type="mesh" mass="0.2" mesh="v_link"/>
                      <site name="s_link8" pos="0 0 0"/>
                      <body name="link9" pos="-0.0685 0 0" gravcomp="0">
                        <joint name="joint9" pos="0.0685 0 0" axis="0 1 0" range="-1.5708 1.5708" armature="0.1" damping="0.42"/>
                        <geom name="link9" type="mesh" mass="0.2" mesh="h_link"/>
                        <site name="s_link9" pos="0 0 0"/>
                        <body name="link10" pos="-0.0685 0 0" gravcomp="0">
                          <joint name="joint10" pos="0.0685 0 0" axis="0 0 1" range="-1.5708 1.5708" armature="0.1" damping="0.42"/>
                          <geom name="link10" type="mesh" mass="0.2" mesh="v_link"/>
                          <site name="s_link10" pos="0 0 0"/>
                          <body name="link11" pos="-0.0685 0 0" gravcomp="0">
                            <joint name="joint11" pos="0.0685 0 0" axis="0 1 0" range="-1.5708 1.5708" armature="0.1" damping="0.42"/>
                            <geom name="link11" type="mesh" mass="0.2" mesh="h_link"/>
                            <site name="s_link11" pos="0 0 0"/>
                            <body name="link12" pos="-0.0685 0 0" gravcomp="0">
                              <joint name="joint12" pos="0.0685 0 0" axis="0 0 1" range="-1.5708 1.5708" armature="0.1" damping="0.42"/>
                              <geom name="link12" type="mesh" mass="0.2" mesh="v_link"/>
                              <site name="s_link12" pos="0 0 0"/>
                              <body name="link13" pos="-0.0685 0 0" gravcomp="0">
                                <joint name="joint13" pos="0.0685 0 0" axis="0 1 0" range="-1.5708 1.5708" armature="0.1" damping="0.42"/>
                                <geom name="link13" type="mesh" mass="0.2" mesh="h_link"/>
                                <site name="s_link13" pos="0 0 0"/>
                                <body name="tail" pos="-0.0413 0 0" gravcomp="0">
                                  <joint name="joint14" pos="0.0413 0 0" axis="0 0 1" range="-1.5708 1.5708" armature="0.1" damping="0.42"/>
                                  <geom name="tail" type="mesh" mass="0.2" mesh="tail_link"/>
                                  <site name="s_tail" pos="0 0 0"/>
                                </body>
                              </body>
                            </body>
                          </body>
                        </body>
                      </body>
                    </body>
                  </body>
                </body>
              </body>
            </body>
          </body>
        </body>
      </body>
    </body>
    <body name="com_marker" pos="0 0 0" gravcomp="0">
      <joint name="com_slidey" pos="0 0 0" axis="1 0 0" type="slide" damping="0.5"/>
      <joint name="com_slidex" pos="0 0 0" axis="0 1 0" type="slide" damping="0.5"/>
      <geom size="0.05" contype="0" conaffinity="0" density="1e-05" rgba="0.8 0.1 0.1 1"/>
    </body>
    <body name="pipe" pos="0.5 0 0.09" quat="0.5 0.5 0.5 0.5" gravcomp="0">
      <geom size="0.0015 0.01425 3.5" pos="0.0885 0 1.75" type="box" rgba="0.6 0.6 0.6 0.2"/>
      <geom size="0.0015 0.01425 3.5" pos="0.084169 0.027348 1.75" quat="0.987688 0 0 0.156434" type="box" rgba="0.6 0.6 0.6 0.2"/>
      <geom size="0.0015 0.01425 3.5" pos="0.071598 0.052019 1.75" quat="0.951057 0 0 0.309017" type="box" rgba="0.6 0.6 0.6 0.2"/>
      <geom size="0.0015 0.01425 3.5" pos="0.052019 0.071598 1.75" quat="0.891007 0 0 0.45399" type="box" rgba="0.6 0.6 0.6 0.2"/>
      <geom size="0.0015 0.01425 3.5" pos="0.027348 0.084169 1.75" quat="0.809017 0 0 0.587785" type="box" rgba="0.6 0.6 0.6 0.2"/>
      <geom size="0.0015 0.01425 3.5" pos="0 0.0885 1.75" quat="0.707107 0 0 0.707107" type="box" rgba="0.6 0.6 0.6 0.2"/>
      <geom size="0.0015 0.01425 3.5" pos="-0.027348 0.084169 1.75" quat="0.587785 0 0 0.809017" type="box" rgba="0.6 0.6 0.6 0.2"/>
      <geom size="0.0015 0.01425 3.5" pos="-0.052019 0.071598 1.75" quat="0.45399 0 0 0.891007" type="box" rgba="0.6 0.6 0.6 0.2"/>
      <geom size="0.0015 0.01425 3.5" pos="-0.071598 0.052019 1.75" quat="0.309017 0 0 0.951057" type="box" rgba="0.6 0.6 0.6 0.2"/>
      <geom size="0.0015 0.01425 3.5" pos="-0.084169 0.027348 1.75" quat="0.156434 0 0 0.987688" type="box" rgba="0.6 0.6 0.6 0.2"/>
      <geom size="0.0015 0.01425 3.5" pos="-0.0885 0 1.75" quat="0 0 0 1" type="box" rgba="0.6 0.6 0.6 0.2"/>
      <geom size="0.0015 0.01425 3.5" pos="-0.084169 -0.027348 1.75" quat="-0.156434 0 0 0.987688" type="box" rgba="0.6 0.6 0.6 0.2"/>
      <geom size="0.0015 0.01425 3.5" pos="-0.071598 -0.052019 1.75" quat="-0.309017 0 0 0.951057" type="box" rgba="0.6 0.6 0.6 0.2"/>
      <geom size="0.0015 0.01425 3.5" pos="-0.052019 -0.071598 1.75" quat="-0.45399 0 0 0.891007" type="box" rgba="0.6 0.6 0.6 0.2"/>
      <geom size="0.0015 0.01425 3.5" pos="-0.027348 -0.084169 1.75" quat="-0.587785 0 0 0.809017" type="box" rgba="0.6 0.6 0.6 0.2"/>
      <geom size="0.0015 0.01425 3.5" pos="0 -0.0885 1.75" quat="-0.707107 0 0 0.707107" type="box" rgba="0.6 0.6 0.6 0.2"/>
      <geom size="0.0015 0.01425 3.5" pos="0.027348 -0.084169 1.75" quat="-0.809017 0 0 0.587785" type="box" rgba="0.6 0.6 0.6 0.2"/>
      <geom size="0.0015 0.01425 3.5" pos="0.052019 -0.071598 1.75" quat="-0.891007 0 0 0.45399" type="box" rgba="0.6 0.6 0.6 0.2"/>
      <geom size="0.0015 0.01425 3.5" pos="0.071598 -0.052019 1.75" quat="-0.951057 0 0 0.309017" type="box" rgba="0.6 0.6 0.6 0.2"/>
      <geom size="0.0015 0.01425 3.5" pos="0.084169 -0.027348 1.75" quat="-0.987688 0 0 0.156434" type="box" rgba="0.6 0.6 0.6 0.2"/>
    </body>
  </worldbody>
  <actuator>
    <general name="servo_1" joint="joint1" ctrlrange="-3 3" actdim="0"/>
    <general name="servo_2" joint="joint2" ctrlrange="-3 3" actdim="0"/>
    <general name="servo_3" joint="joint3" ctrlrange="-3 3" actdim="0"/>
    <general name="servo_4" joint="joint4" ctrlrange="-3 3" actdim="0"/>
    <general name="servo_5" joint="joint5" ctrlrange="-3 3" actdim="0"/>
    <general name="servo_6" joint="joint6" ctrlrange="-3 3" actdim="0"/>
    <general name="servo_7" joint="joint7" ctrlrange="-3 3" actdim="0"/>
    <general name="servo_8" joint="joint8" ctrlrange="-3 3" actdim="0"/>
    <general name="servo_9" joint="joint9" ctrlrange="-3 3" actdim="0"/>
    <general name="servo_10" joint="joint10" ctrlrange="-3 3" actdim="0"/>
    <general name="servo_11" joint="joint11" ctrlrange="-3 3" actdim="0"/>
    <general name="servo_12" joint="joint12" ctrlrange="-3 3" actdim="0"/>
    <general name="servo_13" joint="joint13" ctrlrange="-3 3" actdim="0"/>
    <general name="servo_14" joint="joint14" ctrlrange="-3 3" actdim="0"/>
  </actuator>
  <sensor>
    <accelerometer site="s_head" name="imu_accel" noise="0.005"/>
    <gyro site="s_head" name="imu_gyro" noise="0.005"/>
    <jointpos joint="joint1" name="pos_joint1" noise="0.1"/>
    <jointpos joint="joint2" name="pos_joint2" noise="0.1"/>
    <jointpos joint="joint3" name="pos_joint3" noise="0.1"/>
    <jointpos joint="joint4" name="pos_joint4" noise="0.1"/>
    <jointpos joint="joint5" name="pos_joint5" noise="0.1"/>
    <jointpos joint="joint6" name="pos_joint6" noise="0.1"/>
    <jointpos joint="joint7" name="pos_joint7" noise="0.1"/>
    <jointpos joint="joint8" name="pos_joint8" noise="0.1"/>
    <jointpos joint="joint9" name="pos_joint9" noise="0.1"/>
    <jointpos joint="joint10" name="pos_joint10" noise="0.1"/>
    <jointpos joint="joint11" name="pos_joint11" noise="0.1"/>
    <jointpos joint="joint12" name="pos_joint12" noise="0.1"/>
    <jointpos joint="joint13" name="pos_joint13" noise="0.1"/>
    <jointpos joint="joint14" name="pos_joint14" noise="0.1"/>
    <actuatorvel actuator="servo_1" name="vel_joint1" noise="0.05"/>
    <actuatorvel actuator="servo_2" name="vel_joint2" noise="0.05"/>
    <actuatorvel actuator="servo_3" name="vel_joint3" noise="0.05"/>
    <actuatorvel actuator="servo_4" name="vel_joint4" noise="0.05"/>
    <actuatorvel actuator="servo_5" name="vel_joint5" noise="0.05"/>
    <actuatorvel actuator="servo_6" name="vel_joint6" noise="0.05"/>
    <actuatorvel actuator="servo_7" name="vel_joint7" noise="0.05"/>
    <actuatorvel actuator="servo_8" name="vel_joint8" noise="0.05"/>
    <actuatorvel actuator="servo_9" name="vel_joint9" noise="0.05"/>
    <actuatorvel actuator="servo_10" name="vel_joint10" noise="0.05"/>
    <actuatorvel actuator="servo_11" name="vel_joint11" noise="0.05"/>
    <actuatorvel actuator="servo_12" name="vel_joint12" noise="0.05"/>
    <actuatorvel actuator="servo_13" name="vel_joint13" noise="0.05"/>
    <actuatorvel actuator="servo_14" name="vel_joint14" noise="0.05"/>
    <actuatorfrc actuator="servo_1" name="torque_joint1" noise="0.1"/>
    <actuatorfrc actuator="servo_2" name="torque_joint2" noise="0.1"/>
    <actuatorfrc actuator="servo_3" name="torque_joint3" noise="0.1"/>
    <actuatorfrc actuator="servo_4" name="torque_joint4" noise="0.1"/>
    <actuatorfrc actuator="servo_5" name="torque_joint5" noise="0.1"/>
    <actuatorfrc actuator="servo_6" name="torque_joint6" noise="0.1"/>
    <actuatorfrc actuator="servo_7" name="torque_joint7" noise="0.1"/>
    <actuatorfrc actuator="servo_8" name="torque_joint8" noise="0.1"/>
    <actuatorfrc actuator="servo_9" name="torque_joint9" noise="0.1"/>
    <actuatorfrc actuator="servo_10" name="torque_joint10" noise="0.1"/>
    <actuatorfrc actuator="servo_11" name="torque_joint11" noise="0.1"/>
    <actuatorfrc actuator="servo_12" name="torque_joint12" noise="0.1"/>
    <actuatorfrc actuator="servo_13" name="torque_joint13" noise="0.1"/>
    <actuatorfrc actuator="servo_14" name="torque_joint14" noise="0.1"/>
    <framequat objtype="site" objname="s_head" name="head_quat" noise="0.05"/>
    <framequat objtype="site" objname="s_link1" name="link1_quat" noise="0.05"/>
    <framequat objtype="site" objname="s_link2" name="link2_quat" noise="0.05"/>
    <framequat objtype="site" objname="s_link3" name="link3_quat" noise="0.05"/>
    <framequat objtype="site" objname="s_link4" name="link4_quat" noise="0.05"/>
    <framequat objtype="site" objname="s_link5" name="link5_quat" noise="0.05"/>
    <framequat objtype="site" objname="s_link6" name="link6_quat" noise="0.05"/>
    <framequat objtype="site" objname="s_link7" name="link7_quat" noise="0.05"/>
    <framequat objtype="site" objname="s_link8" name="link8_quat" noise="0.05"/>
    <framequat objtype="site" objname="s_link9" name="link9_quat" noise="0.05"/>
    <framequat objtype="site" objname="s_link10" name="link10_quat" noise="0.05"/>
    <framequat objtype="site" objname="s_link11" name="link11_quat" noise="0.05"/>
    <framequat objtype="site" objname="s_link12" name="link12_quat" noise="0.05"/>
    <framequat objtype="site" objname="s_link13" name="link13_quat" noise="0.05"/>
    <framequat objtype="site" objname="s_tail" name="tail_quat" noise="0.05"/>
    <torque site="s_head" name="head_torque" noise="0.05"/>
  </sensor>
</mujoco>
