<!-- © 2022 Bongsub Song <doorebong@gmail.com> -->
<!-- All right reserved -->
<!-- Description : BRM snake robot Mujoco simulation xml and axis alligned version. -->
<!-- v20220830 : Circular frame version -->
<!-- v20221103 : Body Frame Alligned -->

<mujoco model="snake-dgist">

    <option timestep="0.01"/>

    <asset>
        <texture name="texplane" type="2d" builtin="checker" rgb1=".8 .8 .8" rgb2=".1 0.15 0.2" width="512" height="512" mark="cross" markrgb=".8 .8 .8"/>  

        <texture name="texgeom" type="cube" builtin="flat" mark="cross" width="127" height="1278" 
            rgb1="0.8 0.6 0.4" rgb2="0.8 0.6 0.4" markrgb="1 1 1" random="0.01"/>  

        <material name="matplane" reflectance="0.3" texture="texplane" texrepeat="2 2" texuniform="true"/>

        <material name="matgeom" texture="texgeom" texuniform="true" rgba="0.8 0.6 .4 1"/>

        <hfield name="terrain" ncol="201" nrow="201" size="30 30 5 .1"/>

        <mesh name="head_link" file="./asset/Head.stl"/>
        <mesh name="h_link" file="./asset/Link2.stl"/>
        <mesh name="v_link" file="./asset/Link3.stl"/>
        <mesh name="tail_link" file="./asset/Tail.stl"/>
    </asset>

    <worldbody>

        <geom name="floor" pos="0 0 0" size="0 0 .25" type="plane" material="matplane"/>

        <light directional="false" diffuse="1 1 1" specular="0 0 0" pos="0 0 15" dir="0 0 -1" castshadow="false"/>

        <body name="head" pos="0 0 0.033" euler="0 0 0"> 
            <!-- <freejoint name="root"/> for float joint  -->
            <joint type="slide" axis="1 0 0"/>
            <!-- <joint type="slide" axis="0 1 0"/> -->
            <!-- <joint type="slide" axis="0 0 1"/> -->
            <joint name="r_hinge" type="hinge" axis="1 0 0" frictionloss="1000"/>
            <joint name="p_hinge" type="hinge" axis="0 1 0" frictionloss="0"/>
            <joint name="y_hinge" type="hinge" axis="0 0 1" frictionloss="1000"/>
            <!-- <joint name="r_hinge" type="hinge" axis="1 0 0" frictionloss="1000"/> -->
            <!-- <joint name="p_hinge" type="hinge" axis="0 1 0" frictionloss="1000"/> -->
            <!-- <joint name="y_hinge" type="hinge" axis="0 0 1" frictionloss="1000"/> -->
            <site name="s_head" pos="0 0 0" euler="0 0 0"/>
            <geom name="head" type="mesh" mesh="head_link" mass="0.2"/>

        <body name="link1" pos="-0.0685 0 0" euler="0 0 0">
            <site name="s_link1" pos="0 0 0" euler="0 0 0"/>
            <joint name="joint1" type="hinge" pos="0.0685 0 0" axis="0 1 0" limited="true" range="-90 90" damping="0.42" armature="0.1"/>
            <!-- <joint name="joint1" type="hinge" pos="0.0685 0 0" axis="0 1 0" limited="true" range="-90 90" damping="0.42" armature="0.1"/> -->
            <geom name="link1" type="mesh" mesh="h_link" mass="0.2"/>

        <body name="link2" pos="-0.0685 0 0" euler="0 0 0">
            <site name="s_link2" pos="0 0 0" euler="0 0 0"/>
            <joint name="joint2" type="hinge" pos="0.0685 0 0" axis="0 0 1" limited="true" range="-90 90" damping="0.42" armature="0.1"/>
            <geom name="link2" type="mesh" mesh="v_link" mass="0.2"/>

        <body name="link3" pos="-0.0685 0 0" euler="0 0 0">
            <site name="s_link3" pos="0 0 0" euler="0 0 0"/>
            <joint name="joint3" type="hinge" pos="0.0685 0 0" axis="0 1 0" limited="true" range="-90 90" damping="0.42" armature="0.1"/>
            <geom name="link3" type="mesh" mesh="h_link" mass="0.2"/>
        
        <body name="link4" pos="-0.0685 0 0" euler="0 0 0">
            <site name="s_link4" pos="0 0 0" euler="0 0 0"/>
            <joint name="joint4" type="hinge" pos="0.0685 0 0" axis="0 0 1" limited="true" range="-90 90" damping="0.42" armature="0.1"/>
            <geom name="link4" type="mesh" mesh="v_link" mass="0.2"/>

        <body name="link5" pos="-0.0685 0 0" euler="0 0 0">
            <site name="s_link5" pos="0 0 0" euler="0 0 0"/>
            <joint name="joint5" type="hinge" pos="0.0685 0 0" axis="0 1 0" limited="true" range="-90 90" damping="0.42" armature="0.1"/>
            <geom name="link5" type="mesh" mesh="h_link" mass="0.2"/>

        <body name="link6" pos="-0.0685 0 0" euler="0 0 0">
            <site name="s_link6" pos="0 0 0" euler="0 0 0"/>
            <joint name="joint6" type="hinge" pos="0.0685 0 0" axis="0 0 1" limited="true" range="-90 90" damping="0.42" armature="0.1"/>
            <geom name="link6" type="mesh" mesh="v_link" mass="0.2"/>

        <body name="link7" pos="-0.0685 0 0" euler="0 0 0">
            <site name="s_link7" pos="0 0 0" euler="0 0 0"/>
            <joint name="joint7" type="hinge" pos="0.0685 0 0" axis="0 1 0" limited="true" range="-90 90" damping="0.42" armature="0.1"/>
            <geom name="link7" type="mesh" mesh="h_link" mass="0.2"/>

        <body name="link8" pos="-0.0685 0 0" euler="0 0 0">
            <site name="s_link8" pos="0 0 0" euler="0 0 0"/>
            <joint name="joint8" type="hinge" pos="0.0685 0 0" axis="0 0 1" limited="true" range="-90 90" damping="0.42" armature="0.1"/>
            <geom name="link8" type="mesh" mesh="v_link" mass="0.2"/>

        <body name="link9" pos="-0.0685 0 0" euler="0 0 0">
            <site name="s_link9" pos="0 0 0" euler="0 0 0"/>
            <joint name="joint9" type="hinge" pos="0.0685 0 0" axis="0 1 0" limited="true" range="-90 90" damping="0.42" armature="0.1"/>
            <geom name="link9" type="mesh" mesh="h_link" mass="0.2"/>

        <body name="link10" pos="-0.0685 0 0" euler="0 0 0">
            <site name="s_link10" pos="0 0 0" euler="0 0 0"/>
            <joint name="joint10" type="hinge" pos="0.0685 0 0" axis="0 0 1" limited="true" range="-90 90" damping="0.42" armature="0.1"/>
            <geom name="link10" type="mesh" mesh="v_link" mass="0.2"/>

        <body name="link11" pos="-0.0685 0 0" euler="0 0 0">
            <site name="s_link11" pos="0 0 0" euler="0 0 0"/>
            <joint name="joint11" type="hinge" pos="0.0685 0 0" axis="0 1 0" limited="true" range="-90 90" damping="0.42" armature="0.1"/>
            <geom name="link11" type="mesh" mesh="h_link" mass="0.2"/>

        <body name="link12" pos="-0.0685 0 0" euler="0 0 0">
            <site name="s_link12" pos="0 0 0" euler="0 0 0"/>
            <joint name="joint12" type="hinge" pos="0.0685 0 0" axis="0 0 1" limited="true" range="-90 90" damping="0.42" armature="0.1"/>
            <geom name="link12" type="mesh" mesh="v_link" mass="0.2"/>

        <body name="link13" pos="-0.0685 0 0" euler="0 0 0">
            <site name="s_link13" pos="0 0 0" euler="0 0 0"/>
            <joint name="joint13" type="hinge" pos="0.0685 0 0" axis="0 1 0" limited="true" range="-90 90" damping="0.42" armature="0.1"/>
            <geom name="link13" type="mesh" mesh="h_link" mass="0.2"/>

        <body name="tail" pos="-0.0413 0 0" euler="0 0 0">
            <site name="s_tail" pos="0 0 0" euler="0 0 0"/>
            <joint name="joint14" type="hinge" pos="0.0413 0 0" axis="0 0 1" limited="true" range="-90 90" damping="0.42" armature="0.1"/>
            <geom name="tail" type="mesh" mesh="tail_link" mass="0.2"/>

        </body>
        </body>
        </body>
        </body>
        </body>
        </body>    
        </body>    
        </body>
        </body>
        </body>
        </body>
        </body>
        </body>  
        </body>    
        </body>
    </worldbody>

    <contact>
        <!-- friction="normal tangential" -->
        <pair name="con_head" geom1="floor" geom2="head" condim="3" friction="0.5 0.65"/>
        <pair name="con_link1" geom1="floor" geom2="link1" condim="3" friction="0.5 0.65"/>
        <pair name="con_link2" geom1="floor" geom2="link2" condim="3" friction="0.5 0.65"/>
        <pair name="con_link3" geom1="floor" geom2="link3" condim="3" friction="0.5 0.65"/>
        <pair name="con_link4" geom1="floor" geom2="link4" condim="3" friction="0.5 0.65"/>
        <pair name="con_link5" geom1="floor" geom2="link5" condim="3" friction="0.5 0.65"/>
        <pair name="con_link6" geom1="floor" geom2="link6" condim="3" friction="0.5 0.65"/>
        <pair name="con_link7" geom1="floor" geom2="link7" condim="3" friction="0.5 0.65"/>
        <pair name="con_link8" geom1="floor" geom2="link8" condim="3" friction="0.5 0.65"/>
        <pair name="con_link9" geom1="floor" geom2="link9" condim="3" friction="0.5 0.65"/>
        <pair name="con_link10" geom1="floor" geom2="link10" condim="3" friction="0.5 0.65"/>
        <pair name="con_link11" geom1="floor" geom2="link11" condim="3" friction="0.5 0.65"/>
        <pair name="con_link12" geom1="floor" geom2="link12" condim="3" friction="0.5 0.65"/>
        <pair name="con_link13" geom1="floor" geom2="link13" condim="3" friction="0.5 0.65"/>
        <pair name="con_tail" geom1="floor" geom2="tail" condim="3" friction="0.5 0.65"/>
    </contact>  

    <actuator>
        <motor name="servo_1"  ctrllimited="true" ctrlrange="-3.0 3.0" gear="1" joint="joint1"/>
        <motor name="servo_2"  ctrllimited="true" ctrlrange="-3.0 3.0" gear="1" joint="joint2"/>
        <motor name="servo_3"  ctrllimited="true" ctrlrange="-3.0 3.0" gear="1" joint="joint3"/>
        <motor name="servo_4"  ctrllimited="true" ctrlrange="-3.0 3.0" gear="1" joint="joint4"/>
        <motor name="servo_5"  ctrllimited="true" ctrlrange="-3.0 3.0" gear="1" joint="joint5"/>
        <motor name="servo_6"  ctrllimited="true" ctrlrange="-3.0 3.0" gear="1" joint="joint6"/>
        <motor name="servo_7"  ctrllimited="true" ctrlrange="-3.0 3.0" gear="1" joint="joint7"/>
        <motor name="servo_8"  ctrllimited="true" ctrlrange="-3.0 3.0" gear="1" joint="joint8"/>
        <motor name="servo_9"  ctrllimited="true" ctrlrange="-3.0 3.0" gear="1" joint="joint9"/>
        <motor name="servo_10" ctrllimited="true" ctrlrange="-3.0 3.0" gear="1" joint="joint10"/>
        <motor name="servo_11" ctrllimited="true" ctrlrange="-3.0 3.0" gear="1" joint="joint11"/>
        <motor name="servo_12" ctrllimited="true" ctrlrange="-3.0 3.0" gear="1" joint="joint12"/>
        <motor name="servo_13" ctrllimited="true" ctrlrange="-3.0 3.0" gear="1" joint="joint13"/>
        <motor name="servo_14" ctrllimited="true" ctrlrange="-3.0 3.0" gear="1" joint="joint14"/>
    </actuator>

    <sensor>
        <!-- index 0 - 5 -->
        <accelerometer name="imu_accel" site="s_head"/>
        <gyro name="imu_gyro" site="s_head"/>

        <!-- index 6 - 19 -->
        <jointpos name="pos_joint1" joint="joint1"/>
        <jointpos name="pos_joint2" joint="joint2"/>
        <jointpos name="pos_joint3" joint="joint3"/>
        <jointpos name="pos_joint4" joint="joint4"/>
        <jointpos name="pos_joint5" joint="joint5"/>
        <jointpos name="pos_joint6" joint="joint6"/>
        <jointpos name="pos_joint7" joint="joint7"/>
        <jointpos name="pos_joint8" joint="joint8"/>
        <jointpos name="pos_joint9" joint="joint9"/>
        <jointpos name="pos_joint10" joint="joint10"/>
        <jointpos name="pos_joint11" joint="joint11"/>
        <jointpos name="pos_joint12" joint="joint12"/>
        <jointpos name="pos_joint13" joint="joint13"/>
        <jointpos name="pos_joint14" joint="joint14"/>

        <!-- index 20 - 33 -->
        <actuatorvel name="vel_joint1" actuator="servo_1"/>
        <actuatorvel name="vel_joint2" actuator="servo_2"/>
        <actuatorvel name="vel_joint3" actuator="servo_3"/>
        <actuatorvel name="vel_joint4" actuator="servo_4"/>
        <actuatorvel name="vel_joint5" actuator="servo_5"/>
        <actuatorvel name="vel_joint6" actuator="servo_6"/>
        <actuatorvel name="vel_joint7" actuator="servo_7"/>
        <actuatorvel name="vel_joint8" actuator="servo_8"/>
        <actuatorvel name="vel_joint9" actuator="servo_9"/>
        <actuatorvel name="vel_joint10" actuator="servo_10"/>
        <actuatorvel name="vel_joint11" actuator="servo_11"/>
        <actuatorvel name="vel_joint12" actuator="servo_12"/>
        <actuatorvel name="vel_joint13" actuator="servo_13"/>
        <actuatorvel name="vel_joint14" actuator="servo_14"/>

        <!-- index 34 - 47 -->
        <actuatorfrc name="torque_joint1" actuator="servo_1"/>
        <actuatorfrc name="torque_joint2" actuator="servo_2"/>
        <actuatorfrc name="torque_joint3" actuator="servo_3"/>
        <actuatorfrc name="torque_joint4" actuator="servo_4"/>
        <actuatorfrc name="torque_joint5" actuator="servo_5"/>
        <actuatorfrc name="torque_joint6" actuator="servo_6"/>
        <actuatorfrc name="torque_joint7" actuator="servo_7"/>
        <actuatorfrc name="torque_joint8" actuator="servo_8"/>
        <actuatorfrc name="torque_joint9" actuator="servo_9"/>
        <actuatorfrc name="torque_joint10" actuator="servo_10"/>
        <actuatorfrc name="torque_joint11" actuator="servo_11"/>
        <actuatorfrc name="torque_joint12" actuator="servo_12"/>
        <actuatorfrc name="torque_joint13" actuator="servo_13"/>
        <actuatorfrc name="torque_joint14" actuator="servo_14"/>

        <!-- index 48 - 51 -->
        <framequat name="head_quat" objtype="site" objname="s_head"/>

        <!-- index 52 - 107 -->
        <framequat name="link1_quat" objtype="site" objname="s_link1"/>
        <framequat name="link2_quat" objtype="site" objname="s_link2"/>
        <framequat name="link3_quat" objtype="site" objname="s_link3"/>
        <framequat name="link4_quat" objtype="site" objname="s_link4"/>
        <framequat name="link5_quat" objtype="site" objname="s_link5"/>
        <framequat name="link6_quat" objtype="site" objname="s_link6"/>
        <framequat name="link7_quat" objtype="site" objname="s_link7"/>
        <framequat name="link8_quat" objtype="site" objname="s_link8"/>
        <framequat name="link9_quat" objtype="site" objname="s_link9"/>
        <framequat name="link10_quat" objtype="site" objname="s_link10"/>
        <framequat name="link11_quat" objtype="site" objname="s_link11"/>
        <framequat name="link12_quat" objtype="site" objname="s_link12"/>
        <framequat name="link13_quat" objtype="site" objname="s_link13"/>
        <framequat name="tail_quat" objtype="site" objname="s_tail"/>
        <torque name="head_torque" site="s_head" />

    </sensor>
</mujoco>
