<!-- © 2022 Bongsub Song <doorebong@gmail.com> -->
<!-- All right reserved -->
<!-- Description : BRM snake robot Mujoco simulation xml -->
<!-- v20220614 : Sensor tag added -->

<mujoco model="snake-dgist">

    <option timestep="0.01" iterations="50" tolerance="1e-5" solver="Newton" cone="elliptic"/>
    <size nconmax="3000" njmax="1000" nstack="500000"/>

    <!-- <include file="./common/skybox.xml"/>
    <include file="./common/visual.xml"/>
    <include file="./common/materials.xml"/> -->

    <visual>
        <!-- <rgba rangefinder="1 1 0.1 0.1"/> -->
        <map force="0.005" zfar="20"/>
    </visual>

    <asset>
        <texture type="skybox" builtin="gradient" rgb1="0.5 0.7 0.9" rgb2="0.1 0.1 0.1" width="512" height="512"/> 

        <texture name="texplane" type="2d" builtin="checker" rgb1=".8 .8 .8" rgb2=".1 0.15 0.2" width="512" height="512" mark="cross" markrgb=".8 .8 .8"/>  

        <texture name="texgeom" type="cube" builtin="flat" mark="cross" width="127" height="1278" 
            rgb1="0.8 0.6 0.4" rgb2="0.8 0.6 0.4" markrgb="1 1 1" random="0.01"/>  

        <material name="matplane" reflectance="0.3" texture="texplane" texrepeat="2 2" texuniform="true"/>

        <material name="matgeom" texture="texgeom" texuniform="true" rgba="0.8 0.6 .4 1"/>

        <hfield name="terrain" ncol="201" nrow="201" size="30 30 5 .1"/>
    </asset>

    <option timestep="0.01"/>

    <worldbody>

        <geom name="floor" pos="0 0 0" size="0 0 .25" type="plane" material="matplane" condim="3" friction="0.55 0.01 0.01"/>

        <light directional="false" diffuse="1 1 1" specular="0 0 0" pos="0 0 15" dir="0 0 -1" castshadow="false"/>

    <!-- Snake -->
        <body name="head" pos="0 0 0.033" euler="0 -90 0"> <!--홀-->
            <site name="head" euler="0 90 0"/>
            <freejoint name="root"/>    
            <geom type="cylinder" size="0.0325 0.01" rgba="0.1 0.1 0.1 1" mass="0.04" condim="6" friction="0.55 0.01 0.01"/>
            <geom type="box" size="0.017 0.01425 0.02525" pos="0 0 0.01525" mass="0.1"/>

            <body name="link1" pos="0 0 0.0685"> <!--짝-->
                <joint name="joint1" type="hinge" pos="0 0 -0.02925" axis="0 1 0" limited="true" range="-90 90" damping="0.6" armature="0.01" />
                <geom type="cylinder" size="0.0325 0.01" rgba="0.1 0.1 0.1 1" mass="0.04" condim="6" friction="0.55 0.01 0.01"/>
                <geom type="box" size="0.01425 0.017 0.02525" pos="0 0 0.01525" mass="0.1"/>

                <body name="link2" pos="0 0 0.0685"> <!--홀-->
                    <joint name="joint2" type="hinge" pos="0 0 -0.02925" axis="1 0 0" limited="true" range="-90 90" damping="0.6" armature="0.01" />
                    <geom type="cylinder" size="0.0325 0.01" rgba="0.1 0.1 0.1 1" mass="0.04" condim="6" friction="0.55 0.01 0.01"/>
                    <geom type="box" size="0.017 0.01425 0.02525" pos="0 0 0.01525" mass="0.1"/>

                    <body name="link3" pos="0 0 0.0685"> <!--짝-->
                        <joint name="joint3" type="hinge" pos="0 0 -0.02925" axis="0 1 0" limited="true" range="-90 90" damping="0.6" armature="0.01" />
                        <geom type="cylinder" size="0.0325 0.01" rgba="0.1 0.1 0.1 1" mass="0.04" condim="6" friction="0.55 0.01 0.01"/>
                        <geom type="box" size="0.01425 0.017 0.02525" pos="0 0 0.01525" mass="0.1"/>

                        <body name="link4" pos="0 0 0.0685"> <!--홀-->
                            <joint name="joint4" type="hinge" pos="0 0 -0.02925" axis="1 0 0" limited="true" range="-90 90" damping="0.6" armature="0.01" />
                            <geom type="cylinder" size="0.0325 0.01" rgba="0.1 0.1 0.1 1" mass="0.04" condim="6" friction="0.55 0.01 0.01"/>
                            <geom type="box" size="0.017 0.01425 0.02525" pos="0 0 0.01525" mass="0.1"/>

                            <body name="link5" pos="0 0 0.0685"> <!--짝-->
                                <joint name="joint5" type="hinge" pos="0 0 -0.02925" axis="0 1 0" limited="true" range="-90 90" damping="0.6" armature="0.01" />
                                <geom type="cylinder" size="0.0325 0.01" rgba="0.1 0.1 0.1 1" mass="0.04" condim="6" friction="0.55 0.01 0.01"/>
                                <geom type="box" size="0.01425 0.017 0.02525" pos="0 0 0.01525" mass="0.1"/>

                                <body name="link6" pos="0 0 0.0685"> <!--홀-->
                                    <joint name="joint6" type="hinge" pos="0 0 -0.02925" axis="1 0 0" limited="true" range="-90 90" damping="0.6" armature="0.01" />
                                    <geom type="cylinder" size="0.0325 0.01" rgba="0.1 0.1 0.1 1" mass="0.04" condim="6" friction="0.55 0.01 0.01"/>
                                    <geom type="box" size="0.017 0.01425 0.02525" pos="0 0 0.01525" mass="0.1"/>

                                    <body name="link7" pos="0 0 0.0685"> <!--짝-->
                                        <joint name="joint7" type="hinge" pos="0 0 -0.02925" axis="0 1 0" limited="true" range="-90 90" damping="0.6" armature="0.01" />
                                        <geom type="cylinder" size="0.0325 0.01" rgba="0.1 0.1 0.1 1" mass="0.04" condim="6" friction="0.55 0.01 0.01"/>
                                        <geom type="box" size="0.01425 0.017 0.02525" pos="0 0 0.01525" mass="0.1"/>

                                        <body name="link8" pos="0 0 0.0685"> <!--홀-->
                                            <joint name="joint8" type="hinge" pos="0 0 -0.02925" axis="1 0 0" limited="true" range="-90 90" damping="0.6" armature="0.01" />
                                            <geom type="cylinder" size="0.0325 0.01" rgba="0.1 0.1 0.1 1" mass="0.04" condim="6" friction="0.55 0.01 0.01"/>
                                            <geom type="box" size="0.017 0.01425 0.02525" pos="0 0 0.01525" mass="0.1"/>

                                            <body name="link9" pos="0 0 0.0685"> <!--짝-->
                                                <joint name="joint9" type="hinge" pos="0 0 -0.02925" axis="0 1 0" limited="true" range="-90 90" damping="0.6" armature="0.01" />
                                                <geom type="cylinder" size="0.0325 0.01" rgba="0.1 0.1 0.1 1" mass="0.04" condim="6" friction="0.55 0.01 0.01"/>
                                                <geom type="box" size="0.01425 0.017 0.02525" pos="0 0 0.01525" mass="0.1"/>

                                                <body name="link10" pos="0 0 0.0685"> <!--홀-->
                                                    <joint name="joint10" type="hinge" pos="0 0 -0.02925" axis="1 0 0" limited="true" range="-90 90" damping="0.6" armature="0.01" />
                                                    <geom type="cylinder" size="0.0325 0.01" rgba="0.1 0.1 0.1 1" mass="0.04" condim="6" friction="0.55 0.01 0.01"/>
                                                    <geom type="box" size="0.017 0.01425 0.02525" pos="0 0 0.01525" mass="0.1"/>

                                                    <body name="link11" pos="0 0 0.0685"> <!--짝-->
                                                        <joint name="joint11" type="hinge" pos="0 0 -0.02925" axis="0 1 0" limited="true" range="-90 90" damping="0.6" armature="0.01" />
                                                        <geom type="cylinder" size="0.0325 0.01" rgba="0.1 0.1 0.1 1" mass="0.04" condim="6" friction="0.55 0.01 0.01"/>
                                                        <geom type="box" size="0.01425 0.017 0.02525" pos="0 0 0.01525" mass="0.1"/>

                                                        <body name="link12" pos="0 0 0.0685"> <!--홀-->
                                                            <joint name="joint12" type="hinge" pos="0 0 -0.02925" axis="1 0 0" limited="true" range="-90 90" damping="0.6" armature="0.01" />
                                                            <geom type="cylinder" size="0.0325 0.01" rgba="0.1 0.1 0.1 1" mass="0.04" condim="6" friction="0.55 0.01 0.01"/>
                                                            <geom type="box" size="0.017 0.01425 0.02525" pos="0 0 0.01525" mass="0.1"/>

                                                            <body name="link13" pos="0 0 0.0685"> <!--짝-->
                                                                <joint name="joint13" type="hinge" pos="0 0 -0.02925" axis="0 1 0" limited="true" range="-90 90" damping="0.6" armature="0.01" />
                                                                <geom type="cylinder" size="0.0325 0.01" rgba="0.1 0.1 0.1 1" mass="0.04" condim="6" friction="0.55 0.01 0.01"/>
                                                                <geom type="box" size="0.01425 0.017 0.02525" pos="0 0 0.01525" mass="0.1"/>

                                                                <body name="tail" pos="0 0 0.0685"> <!--홀-->
                                                                    <joint name="joint14" type="hinge" pos="0 0 -0.02925" axis="1 0 0" limited="true" range="-90 90" damping="0.6" armature="0.01" />
                                                                    <geom type="cylinder" size="0.0325 0.01" rgba="0.1 0.1 0.1 1" mass="0.04" condim="6" friction="0.55 0.01 0.01"/>
                                                                    <geom type="box" size="0.017 0.01425 0.02525" pos="0 0 0.01525" mass="0.1"/>
                                                                </body>
                                                            </body>
                                                        </body>
                                                    </body>
                                                </body>
                                            </body>
                                        </body>
                                    </body>
                                </body>
                            </body>
                        </body>
                    </body>
                </body>
            </body>
        </body>
    </worldbody>

    <actuator>
        <position name="servo_1" ctrllimited="true" ctrlrange="-1.5708 1.5708" forcelimited="true" forcerange="-3.0 3.0" gear="1" joint="joint1" kp="70"/>
        <position name="servo_2" ctrllimited="true" ctrlrange="-1.5708 1.5708" forcelimited="true" forcerange="-3.0 3.0" gear="1" joint="joint2" kp="70"/>
        <position name="servo_3" ctrllimited="true" ctrlrange="-1.5708 1.5708" forcelimited="true" forcerange="-3.0 3.0" gear="1" joint="joint3" kp="70"/>
        <position name="servo_4" ctrllimited="true" ctrlrange="-1.5708 1.5708" forcelimited="true" forcerange="-3.0 3.0" gear="1" joint="joint4" kp="70"/>
        <position name="servo_5" ctrllimited="true" ctrlrange="-1.5708 1.5708" forcelimited="true" forcerange="-3.0 3.0" gear="1" joint="joint5" kp="70"/>
        <position name="servo_6" ctrllimited="true" ctrlrange="-1.5708 1.5708" forcelimited="true" forcerange="-3.0 3.0" gear="1" joint="joint6" kp="70"/>
        <position name="servo_7" ctrllimited="true" ctrlrange="-1.5708 1.5708" forcelimited="true" forcerange="-3.0 3.0" gear="1" joint="joint7" kp="70"/>
        <position name="servo_8" ctrllimited="true" ctrlrange="-1.5708 1.5708" forcelimited="true" forcerange="-3.0 3.0" gear="1" joint="joint8" kp="70"/>
        <position name="servo_9" ctrllimited="true" ctrlrange="-1.5708 1.5708" forcelimited="true" forcerange="-3.0 3.0" gear="1" joint="joint9" kp="70"/>
        <position name="servo_10" ctrllimited="true" ctrlrange="-1.5708 1.5708" forcelimited="true" forcerange="-3.0 3.0" gear="1" joint="joint10" kp="70"/>
        <position name="servo_11" ctrllimited="true" ctrlrange="-1.5708 1.5708" forcelimited="true" forcerange="-3.0 3.0" gear="1" joint="joint11" kp="70"/>
        <position name="servo_12" ctrllimited="true" ctrlrange="-1.5708 1.5708" forcelimited="true" forcerange="-3.0 3.0" gear="1" joint="joint12" kp="70"/>
        <position name="servo_13" ctrllimited="true" ctrlrange="-1.5708 1.5708" forcelimited="true" forcerange="-3.0 3.0" gear="1" joint="joint13" kp="70"/>
        <position name="servo_14" ctrllimited="true" ctrlrange="-1.5708 1.5708" forcelimited="true" forcerange="-3.0 3.0" gear="1" joint="joint14" kp="70"/>
    </actuator>

    <sensor>
        <accelerometer name="imu_accel" site="head"/>
        <gyro name="imu_gyro" site="head"/>

        <jointpos name="pos_joint1" joint="joint1"/>
        <jointpos name="pos_joint2" joint="joint2"/>
        <jointpos name="pos_joint3" joint="joint3"/>
        <jointpos name="pos_joint4" joint="joint4"/>
        <jointpos name="pos_joint5" joint="joint5"/>
        <jointpos name="pos_joint6" joint="joint6"/>
        <jointpos name="pos_joint7" joint="joint7"/>
        <jointpos name="pos_joint8" joint="joint8"/>
        <jointpos name="pos_joint9" joint="joint9"/>
        <jointpos name="pos_joint10" joint="joint10"/>
        <jointpos name="pos_joint11" joint="joint11"/>
        <jointpos name="pos_joint12" joint="joint12"/>
        <jointpos name="pos_joint13" joint="joint13"/>
        <jointpos name="pos_joint14" joint="joint14"/>

        <actuatorvel name="vel_joint1" actuator="servo_1"/>
        <actuatorvel name="vel_joint2" actuator="servo_2"/>
        <actuatorvel name="vel_joint3" actuator="servo_3"/>
        <actuatorvel name="vel_joint4" actuator="servo_4"/>
        <actuatorvel name="vel_joint5" actuator="servo_5"/>
        <actuatorvel name="vel_joint6" actuator="servo_6"/>
        <actuatorvel name="vel_joint7" actuator="servo_7"/>
        <actuatorvel name="vel_joint8" actuator="servo_8"/>
        <actuatorvel name="vel_joint9" actuator="servo_9"/>
        <actuatorvel name="vel_joint10" actuator="servo_10"/>
        <actuatorvel name="vel_joint11" actuator="servo_11"/>
        <actuatorvel name="vel_joint12" actuator="servo_12"/>
        <actuatorvel name="vel_joint13" actuator="servo_13"/>
        <actuatorvel name="vel_joint14" actuator="servo_14"/>

        <actuatorfrc name="torque_joint1" actuator="servo_1"/>
        <actuatorfrc name="torque_joint2" actuator="servo_2"/>
        <actuatorfrc name="torque_joint3" actuator="servo_3"/>
        <actuatorfrc name="torque_joint4" actuator="servo_4"/>
        <actuatorfrc name="torque_joint5" actuator="servo_5"/>
        <actuatorfrc name="torque_joint6" actuator="servo_6"/>
        <actuatorfrc name="torque_joint7" actuator="servo_7"/>
        <actuatorfrc name="torque_joint8" actuator="servo_8"/>
        <actuatorfrc name="torque_joint9" actuator="servo_9"/>
        <actuatorfrc name="torque_joint10" actuator="servo_10"/>
        <actuatorfrc name="torque_joint11" actuator="servo_11"/>
        <actuatorfrc name="torque_joint12" actuator="servo_12"/>
        <actuatorfrc name="torque_joint13" actuator="servo_13"/>
        <actuatorfrc name="torque_joint14" actuator="servo_14"/>

        <framequat name="head_quat" objtype="site" objname="head"/>
        <!-- <framequat name="head_quat" objtype="geom" objname="floor" reftype="site" refname="head"/> -->
    </sensor>

</mujoco>
