 <!-- © 2021 Bongsub Song <doorebong@gmail.com> -->
 <!-- All right reserved -->
 <!-- Description : BRM snake robot Mujoco simulation xml -->

<mujoco model="snake_v210709">

    <compiler inertiafromgeom="true" angle="degree" convexhull="false"/>

    <option timestep="0.005" iterations="50" tolerance="1e-10" solver="Newton" jacobian="dense" cone="pyramidal"/>

    <size nconmax="500" njmax="2000" nstack="10000"/>

    <visual>
        <map force="0.1" zfar="30"/>
        <rgba haze="0.15 0.25 0.35 1"/>
        <quality shadowsize="2048"/>
        <global offwidth="800" offheight="800"/>
    </visual>

    <asset>
        <texture type="skybox" builtin="gradient" rgb1="0.3 0.5 0.7" rgb2="0 0 0" width="512" height="512"/> 

    <!-- texture for ground -->
        <texture name="texplane" type="2d" builtin="checker" rgb1=".2 .3 .4" rgb2=".1 0.15 0.2" width="512" height="512" mark="cross" markrgb=".8 .8 .8"/>  
        <texture name="grass" type="2d" file="./asset/grass.png"/>

        <texture name="texgeom" type="cube" builtin="flat" mark="cross" width="127" height="1278" 
            rgb1="0.8 0.6 0.4" rgb2="0.8 0.6 0.4" markrgb="1 1 1" random="0.01"/>  

        <material name="matplane" reflectance="0.3" texture="texplane" texrepeat="1 1" texuniform="true"/>

        <material name="matgeom" texture="texgeom" texuniform="true" rgba="0.8 0.6 .4 1"/>

        <!-- Pipe Meshes -->
        <mesh name="pipe100" file="./asset/Pipe-100mm-3T_low.stl"/>
    </asset>

    <worldbody>

        <geom name="floor" pos="0 0 0" size="0 0 .25" type="plane" material="matplane" condim="3" />

        <light directional="false" diffuse=".2 .2 .2" specular="0 0 0" pos="0 0 5" dir="0 0 -1" castshadow="false"/>

    <!-- Pipes -->
        <body pos="-0.025 0 0.0">
            <freejoint name="pipe1"/>
            <geom type="mesh" mesh="pipe100"/>
        </body>

    <!-- Snake -->
        <body name="head" pos="0 0 0.1">
        <freejoint name="snake_root"/>
        <inertial pos="0 0 0" quat="0 0.707107 0 0.707107" mass="0.1" diaginertia="0.0000194 0.0000174 0.0000115" />
        <geom size="0.02325 0.017 0.01425" type="box" friction="0 0 0.005" rgba="0.9 0.9 0.9 1"/>

            <body name="body1" pos="-0.0685 0 0">
            <joint name="joint1" type="hinge" pos="0.0565 0 0" axis="0 1 0" limited="true" range="-90 90" damping="0.6" stiffness="0" armature="0.05" />
            <inertial pos="0 0 0" quat="0 0.707107 0 0.707107" mass="0.1" diaginertia="0.0000194 0.0000174 0.0000115" />
            <geom size="0.02325 0.01425 0.017" pos="0 0 0" type="box" friction="0 0 0.005" rgba="0.2 0.2 0.2 1"/>
                
                <body name="body2" pos="-0.0685 0 0">
                <joint name="joint2" type="hinge" pos="0.0565 0 0" axis="0 0 1" limited="true" range="-90 90" damping="0.6" stiffness="0" armature="0.05" />
                <inertial pos="0 0 0" quat="0 0.707107 0 0.707107" mass="0.1" diaginertia="0.0000194 0.0000174 0.0000115" />
                <geom size="0.02325 0.017 0.01425" type="box" friction="0 0 0.005" rgba="0.9 0.9 0.9 1"/>

                    <body name="body3" pos="-0.0685 0 0">
                    <joint name="joint3" type="hinge" pos="0.0565 0 0" axis="0 1 0" limited="true" range="-90 90" damping="0.6" stiffness="0" armature="0.05" />
                    <inertial pos="0 0 0" quat="0 0.707107 0 0.707107" mass="0.1" diaginertia="0.0000194 0.0000174 0.0000115" />
                    <geom size="0.02325 0.01425 0.017" pos="0 0 0" type="box" friction="0 0 0.005" rgba="0.2 0.2 0.2 1"/>

                        <body name="body4" pos="-0.0685 0 0">
                        <joint name="joint4" type="hinge" pos="0.0565 0 0" axis="0 0 1" limited="true" range="-90 90" damping="0.6" stiffness="0" armature="0.05" />
                        <inertial pos="0 0 0" quat="0 0.707107 0 0.707107" mass="0.1" diaginertia="0.0000194 0.0000174 0.0000115" />
                        <geom size="0.02325 0.017 0.01425" type="box" friction="0 0 0.005" rgba="0.9 0.9 0.9 1"/>

                            <body name="body5" pos="-0.0685 0 0">
                            <joint name="joint5" type="hinge" pos="0.0565 0 0" axis="0 1 0" limited="true" range="-90 90" damping="0.6" stiffness="0" armature="0.05" />
                            <inertial pos="0 0 0" quat="0 0.707107 0 0.707107" mass="0.1" diaginertia="0.0000194 0.0000174 0.0000115" />
                            <geom size="0.02325 0.01425 0.017" pos="0 0 0" type="box" friction="0 0 0.005" rgba="0.2 0.2 0.2 1"/>

                                <body name="body6" pos="-0.0685 0 0">
                                <joint name="joint6" type="hinge" pos="0.0565 0 0" axis="0 0 1" limited="true" range="-90 90" damping="0.6" stiffness="0" armature="0.05" />
                                <inertial pos="0 0 0" quat="0 0.707107 0 0.707107" mass="0.1" diaginertia="0.0000194 0.0000174 0.0000115" />
                                <geom size="0.02325 0.017 0.01425" type="box" friction="0 0 0.005" rgba="0.9 0.9 0.9 1"/>

                                    <body name="body7" pos="-0.0685 0 0">
                                    <joint name="joint7" type="hinge" pos="0.0565 0 0" axis="0 1 0" limited="true" range="-90 90" damping="0.6" stiffness="0" armature="0.05" />
                                    <inertial pos="0 0 0" quat="0 0.707107 0 0.707107" mass="0.1" diaginertia="0.0000194 0.0000174 0.0000115" />
                                    <geom size="0.02325 0.01425 0.017" pos="0 0 0" type="box" friction="0 0 0.005" rgba="0.2 0.2 0.2 1"/>

                                        <body name="body8" pos="-0.0685 0 0">
                                        <joint name="joint8" type="hinge" pos="0.0565 0 0" axis="0 0 1" limited="true" range="-90 90" damping="0.6" stiffness="0" armature="0.05" />
                                        <inertial pos="0 0 0" quat="0 0.707107 0 0.707107" mass="0.1" diaginertia="0.0000194 0.0000174 0.0000115" />
                                        <geom size="0.02325 0.017 0.01425" type="box" friction="0 0 0.005" rgba="0.9 0.9 0.9 1"/>

                                            <body name="body9" pos="-0.0685 0 0">
                                            <joint name="joint9" type="hinge" pos="0.0565 0 0" axis="0 1 0" limited="true" range="-90 90" damping="0.6" stiffness="0" armature="0.05" />
                                            <inertial pos="0 0 0" quat="0 0.707107 0 0.707107" mass="0.1" diaginertia="0.0000194 0.0000174 0.0000115" />
                                            <geom size="0.02325 0.01425 0.017" pos="0 0 0" type="box" friction="0 0 0.005" rgba="0.2 0.2 0.2 1"/>

                                                <body name="body10" pos="-0.0685 0 0">
                                                <joint name="joint10" type="hinge" pos="0.0565 0 0" axis="0 0 1" limited="true" range="-90 90" damping="0.6" stiffness="0" armature="0.05" />
                                                <inertial pos="0 0 0" quat="0 0.707107 0 0.707107" mass="0.1" diaginertia="0.0000194 0.0000174 0.0000115" />
                                                <geom size="0.02325 0.017 0.01425" type="box" friction="0 0 0.005" rgba="0.9 0.9 0.9 1"/>

                                                    <body name="body11" pos="-0.0685 0 0">
                                                    <joint name="joint11" type="hinge" pos="0.0565 0 0" axis="0 1 0" limited="true" range="-90 90" damping="0.6" stiffness="0" armature="0.05" />
                                                    <inertial pos="0 0 0" quat="0 0.707107 0 0.707107" mass="0.1" diaginertia="0.0000194 0.0000174 0.0000115" />
                                                    <geom size="0.02325 0.01425 0.017" pos="0 0 0" type="box" friction="0 0 0.005" rgba="0.2 0.2 0.2 1"/>

                                                        <body name="body12" pos="-0.0685 0 0">
                                                        <joint name="joint12" type="hinge" pos="0.0565 0 0" axis="0 0 1" limited="true" range="-90 90" damping="0.6" stiffness="0" armature="0.05" />
                                                        <inertial pos="0 0 0" quat="0 0.707107 0 0.707107" mass="0.1" diaginertia="0.0000194 0.0000174 0.0000115" />
                                                        <geom size="0.02325 0.017 0.01425" type="box" friction="0 0 0.005" rgba="0.9 0.9 0.9 1"/>

                                                            <body name="body13" pos="-0.0685 0 0">
                                                            <joint name="joint13" type="hinge" pos="0.0565 0 0" axis="0 1 0" limited="true" range="-90 90" damping="0.6" stiffness="0" armature="0.05" />
                                                            <inertial pos="0 0 0" quat="0 0.707107 0 0.707107" mass="0.1" diaginertia="0.0000194 0.0000174 0.0000115" />
                                                            <geom size="0.02325 0.01425 0.017" pos="0 0 0" type="box" friction="0 0 0.005" rgba="0.2 0.2 0.2 1"/>

                                                                <body name="body14" pos="-0.0685 0 0">
                                                                <joint name="joint14" type="hinge" pos="0.0565 0 0" axis="0 0 1" limited="true" range="-90 90" damping="0.6" stiffness="0" armature="0.05" />
                                                                <inertial pos="0 0 0" quat="0 0.707107 0 0.707107" mass="0.1" diaginertia="0.0000194 0.0000174 0.0000115" />
                                                                <geom size="0.02325 0.017 0.01425" type="box" friction="0 0 0.005" rgba="0.9 0.9 0.9 1"/>

                                                                    <body name="tail" pos="-0.0685 0 0">
                                                                    <joint name="joint15" type="hinge" pos="0.0565 0 0" axis="0 1 0" limited="true" range="-90 90" damping="0.6" stiffness="0" armature="0.05" />
                                                                    <inertial pos="0 0 0" quat="0 0.707107 0 0.707107" mass="0.1" diaginertia="0.0000194 0.0000174 0.0000115" />
                                                                    <geom size="0.02325 0.01425 0.017" pos="0 0 0" type="box" friction="0 0 0.005" rgba="0.2 0.2 0.2 1"/>
                                                                    </body>
                                                                </body>
                                                            </body>
                                                        </body>
                                                    </body>
                                                </body>
                                            </body>
                                        </body>
                                    </body>
                                </body>
                            </body>
                        </body>
                    </body>
                </body>
            </body>
        </body>

    </worldbody>

    <actuator>
        <position name="servo_1" ctrllimited="true" ctrlrange="-1.5708 1.5708" forcelimited="true" forcerange="-3.0 3.0" gear="1" joint="joint1" kp="4"/>
        <position name="servo_2" ctrllimited="true" ctrlrange="-1.5708 1.5708" forcelimited="true" forcerange="-3.0 3.0" gear="1" joint="joint2" kp="4"/>
        <position name="servo_3" ctrllimited="true" ctrlrange="-1.5708 1.5708" forcelimited="true" forcerange="-3.0 3.0" gear="1" joint="joint3" kp="4"/>
        <position name="servo_4" ctrllimited="true" ctrlrange="-1.5708 1.5708" forcelimited="true" forcerange="-3.0 3.0" gear="1" joint="joint4" kp="4"/>
        <position name="servo_5" ctrllimited="true" ctrlrange="-1.5708 1.5708" forcelimited="true" forcerange="-3.0 3.0" gear="1" joint="joint5" kp="4"/>
        <position name="servo_6" ctrllimited="true" ctrlrange="-1.5708 1.5708" forcelimited="true" forcerange="-3.0 3.0" gear="1" joint="joint6" kp="4"/>
        <position name="servo_7" ctrllimited="true" ctrlrange="-1.5708 1.5708" forcelimited="true" forcerange="-3.0 3.0" gear="1" joint="joint7" kp="4"/>
        <position name="servo_8" ctrllimited="true" ctrlrange="-1.5708 1.5708" forcelimited="true" forcerange="-3.0 3.0" gear="1" joint="joint8" kp="4"/>
        <position name="servo_9" ctrllimited="true" ctrlrange="-1.5708 1.5708" forcelimited="true" forcerange="-3.0 3.0" gear="1" joint="joint9" kp="4"/>
        <position name="servo_10" ctrllimited="true" ctrlrange="-1.5708 1.5708" forcelimited="true" forcerange="-3.0 3.0" gear="1" joint="joint10" kp="4"/>
        <position name="servo_11" ctrllimited="true" ctrlrange="-1.5708 1.5708" forcelimited="true" forcerange="-3.0 3.0" gear="1" joint="joint11" kp="4"/>
        <position name="servo_12" ctrllimited="true" ctrlrange="-1.5708 1.5708" forcelimited="true" forcerange="-3.0 3.0" gear="1" joint="joint12" kp="4"/>
        <position name="servo_13" ctrllimited="true" ctrlrange="-1.5708 1.5708" forcelimited="true" forcerange="-3.0 3.0" gear="1" joint="joint13" kp="4"/>
        <position name="servo_14" ctrllimited="true" ctrlrange="-1.5708 1.5708" forcelimited="true" forcerange="-3.0 3.0" gear="1" joint="joint14" kp="4"/>
        <position name="servo_15" ctrllimited="true" ctrlrange="-1.5708 1.5708" forcelimited="true" forcerange="-3.0 3.0" gear="1" joint="joint15" kp="4"/>

    </actuator>
</mujoco>
